[
  {
    "project": "openai/openai-python",
    "commit": "40c32f9f4e05eb19966942839f2800a8d810e81b",
    "filename": "openai/six.py",
    "min_patch_found": false,
    "full_warning_msg": "openai/six.py:49:19 Unbound name [10]: Name `basestring` is used but not defined in the current scope.",
    "exception": "[Errno 2] No such file or directory: '/home/chowyi/TypeAnnotation_Study/GitHub/openai-openai-python/openai/six.py'",
    "dd_fail": true
  },
  {
    "project": "openai/openai-python",
    "commit": "40c32f9f4e05eb19966942839f2800a8d810e81b",
    "filename": "openai/six.py",
    "min_patch_found": false,
    "full_warning_msg": "openai/six.py:50:26 Unbound name [10]: Name `long` is used but not defined in the current scope.",
    "exception": "[Errno 2] No such file or directory: '/home/chowyi/TypeAnnotation_Study/GitHub/openai-openai-python/openai/six.py'",
    "dd_fail": true
  },
  {
    "project": "openai/openai-python",
    "commit": "40c32f9f4e05eb19966942839f2800a8d810e81b",
    "filename": "openai/six.py",
    "min_patch_found": false,
    "full_warning_msg": "openai/six.py:52:16 Unbound name [10]: Name `unicode` is used but not defined in the current scope.",
    "exception": "[Errno 2] No such file or directory: '/home/chowyi/TypeAnnotation_Study/GitHub/openai-openai-python/openai/six.py'",
    "dd_fail": true
  },
  {
    "project": "openai/openai-python",
    "commit": "40c32f9f4e05eb19966942839f2800a8d810e81b",
    "filename": "openai/six.py",
    "min_patch_found": false,
    "full_warning_msg": "openai/six.py:545:4 Incompatible variable type [9]: create_bound_method is declared to have type `typing.Callable(create_bound_method)[[Named(func, unknown), Named(obj, unknown)], typing.Any]` but is used as type `typing.Type[types.MethodType]`.",
    "exception": "[Errno 2] No such file or directory: '/home/chowyi/TypeAnnotation_Study/GitHub/openai-openai-python/openai/six.py'",
    "dd_fail": true
  },
  {
    "project": "openai/openai-python",
    "commit": "40c32f9f4e05eb19966942839f2800a8d810e81b",
    "filename": "openai/six.py",
    "min_patch_found": false,
    "full_warning_msg": "openai/six.py:634:4 Incompatible variable type [9]: byte2int is declared to have type `typing.Callable(byte2int)[[Named(bs, unknown)], typing.Any]` but is used as type `operator.itemgetter[typing.Any]`.",
    "exception": "[Errno 2] No such file or directory: '/home/chowyi/TypeAnnotation_Study/GitHub/openai-openai-python/openai/six.py'",
    "dd_fail": true
  },
  {
    "project": "openai/openai-python",
    "commit": "40c32f9f4e05eb19966942839f2800a8d810e81b",
    "filename": "openai/six.py",
    "min_patch_found": false,
    "full_warning_msg": "openai/six.py:953:21 Incompatible parameter type [6]: Expected `sys._MetaPathFinder` for 1st positional only parameter to call `list.append` but got `_SixMetaPathImporter`.",
    "exception": "[Errno 2] No such file or directory: '/home/chowyi/TypeAnnotation_Study/GitHub/openai-openai-python/openai/six.py'",
    "dd_fail": true
  }
]