[
  {
    "project": "bryanthowell-tableau/tableau_tools",
    "commit": "169f4235253f9bf7b7d92675031b71dbbf3212d0",
    "filename": "tableau_documents/tableau_datasource.py",
    "filename_after_commit": "/home/chowyi/TypeAnnotation_Study/GitHub/bryanthowell-tableau-tableau_tools/tableau_documents/tableau_datasource.py",
    "file_hunks_size": 7,
    "min_patch_found": false,
    "single_hunk": false,
    "fit_TFix": false,
    "delete_only_patch": false,
    "has_suppression_all_hunks": false,
    "full_warning_msg": "tableau_documents/tableau_datasource.py:436:18 Unbound name [10]: Name `AlreadyExistsException` is used but not defined in the current scope.",
    "message": " Name `AlreadyExistsException` is used but not defined in the current scope.",
    "rule_id": "Unbound name [10]",
    "warning_line_no": 436,
    "warning_line": "            raise AlreadyExistsException(\"An extract already exists, can't add a new one\", \"\")"
  }
]